Workbook

Sheet Adições e Exclusões
B2: ='Acomp. Resultados_2026'!B5:AA5 -> NOME DA EMPRESA
B5: Adições e Exclusões_2026
C7: JAN | D7: FEV | E7: MAR | F7: ABR | G7: MAI | H7: JUN | I7: JUL | J7: AGO | K7: SET | L7: OUT | M7: NOV | N7: DEZ | O7: ANUAL
B9: ADIÇÕES (ACUMULADO)
A10: 6250 | B10: (+) Despesas Indedutíveis | O10: =SUM(C10:N10) -> 0
A11: 6109 | B11: (+) Outros Gastos com Pessoal | O11: =SUM(C11:N11) -> 0
A12: 3325 | B12: (+) Brindes | O12: =SUM(C12:N12) -> 0
A13: 6257 | B13: (+) Multas Fiscais | O13: =SUM(C13:N13) -> 0
A14: 6119 | B14: (+) Multas de Trânsito | O14: =SUM(C14:N14) -> 0
B15: (+) Depreciação acelerada | O15: =SUM(C15:N15) -> 0
B16: Total das adições (acumulado) | C16: =C10+C11+C13+C15 -> 0 | D16: =D10+D11+D13+D15 -> 0 | E16: =E10+E11+E13+E15 -> 0 | F16: =SUM(F10:F15) -> 0 | G16: =SUM(G10:G15) -> 0 | H16: =SUM(H10:H15) -> 0 | I16: =SUM(I10:I15) -> 0 | J16: =SUM(J10:J15) -> 0 | K16: =SUM(K10:K15) -> 0 | L16: =SUM(L10:L15) -> 0 | M16: =SUM(M10:M15) -> 0 | ... O16: =SUM(O10:O15) -> 0
B18: EXCLUSÕES (ACUMULADO)
B19: (-) Selic | C19: 0 | D19: =C19 -> 0 | E19: =D19 -> 0 | F19: =E19 -> 0 | G19: =F19 -> 0 | H19: =G19 -> 0 | I19: =H19 -> 0 | J19: =I19 -> 0 | K19: =J19 -> 0 | ... N19: =M19 -> 0 | O19: =SUM(C19:N19) -> 0
B20: Total das exclusões (acumulado) | C20: =C19 -> 0 | D20: =D19 -> 0 | E20: =E19 -> 0 | F20: =F19 -> 0 | G20: =G19 -> 0 | H20: =H19 -> 0 | I20: =I19 -> 0 | J20: =J19 -> 0 | ... O20: =O19 -> 0

Sheet Acomp. Resultados_2026
B3: ACOMPANHAMENTO DE RESULTADO CONTÁBIL_2026
B5: NOME DA EMPRESA
B6: CNPJ DA EMPRESA:
B8: ACOMPANHAMENTO DE RESULTADO_2026
C12: JAN | D12: % | E12: FEV | F12: % | G12: MAR | H12: % | I12: ABR | J12: % | K12: MAI | L12: % | M12: JUN | N12: % | O12: JUL | P12: % | Q12: AGO | R12: % | S12: SET | T12: % | U12: OUT | V12: % | W12: NOV | X12: % | Y12: DEZ | Z12: % | AA12: ANUAL | AB12: %
A13: 994 | B13: (+) Receita de Venda de Mercadorias | AA13: =SUM(C13,E13,G13,I13,K13,M13,O13,Q13,S13,U13,W13,Y13) -> 0
A14: 1022 | B14: (+) Receita de Venda de Produtos | AA14: =SUM(C14,E14,G14,I14,K14,M14,O14,Q14,S14,U14,W14,Y14) -> 0
A15: 1085 | B15: (+) Receita de Transportes | AA15: =SUM(C15,E15,G15,I15,K15,M15,O15,Q15,S15,U15,W15,Y15) -> 0
A16: 1176 | B16: (+) Receita de Serviços | AA16: =SUM(C16,E16,G16,I16,K16,M16,O16,Q16,S16,U16,W16,Y16) -> 0
A17: 5139 | B17: (+) Receita de Locação | AA17: =SUM(C17,E17,G17,I17,K17,M17,O17,Q17,S17,U17,W17,Y17) -> 0
A18: 1197 | B18: (+) Receita Financeira | AA18: =SUM(C18,E18,G18,I18,K18,M18,O18,Q18,S18,U18,W18,Y18) -> 0
A19: 3276 | B19: (+) Receita de venda de Bens Imóveis | AA19: =SUM(C19,E19,G19,I19,K19,M19,O19,Q19,S19,U19,W19,Y19) -> 0
B20: (+) Demais receitas com vendas | AA20: =SUM(C20,E20,G20,I20,K20,M20,O20,Q20,S20,U20,W20,Y20) -> 0
B21: (+) Receita de Exportação de Produtos | AA21: =SUM(C21,E21,G21,I21,K21,M21,O21,Q21,S21,U21,W21,Y21) -> 0
B22: (+) Receita de Exportação de Mercadoria | AA22: =SUM(C22,E22,G22,I22,K22,M22,O22,Q22,S22,U22,W22,Y22) -> 0
B23: (+) Receita de Cartulas | AA23: =SUM(C23,E23,G23,I23,K23,M23,O23,Q23,S23,U23,W23,Y23) -> 0
B24: (-) Devoluções | AA24: =SUM(C24,E24,G24,I24,K24,M24,O24,Q24,S24,U24,W24,Y24) -> 0
B25: Receita Líquida | C25: =SUM(C13:C24) -> 0 | E25: =SUM(E13:E24) -> 0 | G25: =SUM(G13:G24) -> 0 | I25: =SUM(I13:I24) -> 0 | K25: =SUM(K13:K24) -> 0 | M25: =SUM(M13:M24) -> 0 | O25: =SUM(O13:O24) -> 0 | Q25: =SUM(Q13:Q24) -> 0 | S25: =SUM(S13:S24) -> 0 | U25: =SUM(U13:U24) -> 0 | W25: =SUM(W13:W24) -> 0 | Y25: =SUM(Y13:Y24) -> 0 | AA25: =SUM(AA13:AA24) -> 0
B27: (-) Outras Deduções | D27: =IFERROR((C27/C25),0) -> 0 | F27: =IFERROR((E27/E25),0) -> 0 | H27: =IFERROR((G27/G25),0) -> 0 | J27: =IFERROR((I27/I25),0) -> 0 | L27: =IFERROR((K27/K25),0) -> 0 | N27: =IFERROR((M27/M25),0) -> 0 | P27: =IFERROR((O27/O25),0) -> 0 | R27: =IFERROR((Q27/Q25),0) -> 0 | T27: =IFERROR((S27/S25),0) -> 0 | V27: =IFERROR((U27/U25),0) -> 0 | X27: =IFERROR((W27/W25),0) -> 0 | Z27: =IFERROR((Y27/Y25),0) -> 0 | AA27: =SUM(C27:Y27) -> 0 | AB27: =IFERROR((AA27/AA25),0) -> 0
B28: Outras Deduções da Receita | C28: =C27 -> 0 | E28: =E27 -> 0 | G28: =G27 -> 0 | I28: =I27 -> 0 | K28: =K27 -> 0 | M28: =M27 -> 0 | O28: =O27 -> 0 | Q28: =Q27 -> 0 | S28: =S27 -> 0 | U28: =U27 -> 0 | W28: =W27 -> 0 | Y28: =Y27 -> 0 | AA28: =AA27 -> 0
B30: (+) Incentivos Fiscais | AA30: =SUM(C30,E30,G30,I30,K30,M30,O30,Q30,S30,U30,W30,Y30) -> 0
B31: Incentivos Fiscais | C31: =C30 -> 0 | E31: =E30 -> 0 | G31: =G30 -> 0 | I31: =I30 -> 0 | K31: =K30 -> 0 | M31: =M30 -> 0 | O31: =O30 -> 0 | Q31: =Q30 -> 0 | S31: =S30 -> 0 | U31: =U30 -> 0 | W31: =W30 -> 0 | Y31: =Y30 -> 0 | AA31: =AA30 -> 0
B33: (-) CMV | D33: =IFERROR((C33/C25),0) -> 0 | F33: =IFERROR((E33/E25),0) -> 0 | H33: =IFERROR((G33/G25),0) -> 0 | J33: =IFERROR((I33/I25),0) -> 0 | L33: =IFERROR((K33/K25),0) -> 0 | N33: =IFERROR((M33/M25),0) -> 0 | P33: =IFERROR((O33/O25),0) -> 0 | R33: =IFERROR((Q33/Q25),0) -> 0 | T33: =IFERROR((S33/S25),0) -> 0 | V33: =IFERROR((U33/U25),0) -> 0 | X33: =IFERROR((W33/W25),0) -> 0 | Z33: =IFERROR((Y33/Y25),0) -> 0 | AA33: =SUM(C33,E33,G33,I33,K33,M33,O33,Q33,S33,U33,W33,Y33) -> 0 | AB33: =IFERROR((AA33/AA25),0) -> 0
B34: (-) CPV | D34: =IFERROR((C34/C25),0) -> 0 | F34: =IFERROR((E34/E25),0) -> 0 | H34: =IFERROR((G34/G25),0) -> 0 | J34: =IFERROR((I34/I25),0) -> 0 | L34: =IFERROR((K34/K25),0) -> 0 | N34: =IFERROR((M34/M25),0) -> 0 | P34: =IFERROR((O34/O25),0) -> 0 | R34: =IFERROR((Q34/Q25),0) -> 0 | T34: =IFERROR((S34/S25),0) -> 0 | V34: =IFERROR((U34/U25),0) -> 0 | X34: =IFERROR((W34/W25),0) -> 0 | Z34: =IFERROR((Y34/Y25),0) -> 0 | AA34: =SUM(C34,E34,G34,I34,K34,M34,O34,Q34,S34,U34,W34,Y34) -> 0 | AB34: =IFERROR((AA34/AA25),0) -> 0
B35: (-) CSP | D35: =IFERROR((C35/C25),0) -> 0 | F35: =IFERROR((E35/E25),0) -> 0 | H35: =IFERROR((G35/G25),0) -> 0 | J35: =IFERROR((I35/I25),0) -> 0 | L35: =IFERROR((K35/K25),0) -> 0 | N35: =IFERROR((M35/M25),0) -> 0 | P35: =IFERROR((O35/O25),0) -> 0 | R35: =IFERROR((Q35/Q25),0) -> 0 | T35: =IFERROR((S35/S25),0) -> 0 | V35: =IFERROR((U35/U25),0) -> 0 | X35: =IFERROR((W35/W25),0) -> 0 | Z35: =IFERROR((Y35/Y25),0) -> 0 | AA35: =SUM(C35,E35,G35,I35,K35,M35,O35,Q35,S35,U35,W35,Y35) -> 0 | AB35: =IFERROR((AA35/AA25),0) -> 0
B36: (-) Custos com Produção | D36: =IFERROR((C36/C25),0) -> 0 | F36: =IFERROR((E36/E25),0) -> 0 | H36: =IFERROR((G36/G25),0) -> 0 | J36: =IFERROR((I36/I25),0) -> 0 | L36: =IFERROR((K36/K25),0) -> 0 | N36: =IFERROR((M36/M25),0) -> 0 | P36: =IFERROR((O36/O25),0) -> 0 | R36: =IFERROR((Q36/Q25),0) -> 0 | T36: =IFERROR((S36/S25),0) -> 0 | V36: =IFERROR((U36/U25),0) -> 0 | X36: =IFERROR((W36/W25),0) -> 0 | Z36: =IFERROR((Y36/Y25),0) -> 0 | AA36: =SUM(C36,E36,G36,I36,K36,M36,O36,Q36,S36,U36,W36,Y36) -> 0 | AB36: =IFERROR((AA36/AA25),0) -> 0
B37: (-) Custos Alienação | D37: =IFERROR((C37/C25),0) -> 0 | F37: =IFERROR((E37/E25),0) -> 0 | H37: =IFERROR((G37/G25),0) -> 0 | J37: =IFERROR((I37/I25),0) -> 0 | L37: =IFERROR((K37/K25),0) -> 0 | N37: =IFERROR((M37/M25),0) -> 0 | P37: =IFERROR((O37/O25),0) -> 0 | R37: =IFERROR((Q37/Q25),0) -> 0 | T37: =IFERROR((S37/S25),0) -> 0 | V37: =IFERROR((U37/U25),0) -> 0 | X37: =IFERROR((W37/W25),0) -> 0 | Z37: =IFERROR((Y37/Y25),0) -> 0 | AA37: =SUM(C37,E37,G37,I37,K37,M37,O37,Q37,S37,U37,W37,Y37) -> 0 | AB37: =IFERROR((AA37/AA25),0) -> 0
B38: Custo Total | C38: =SUM(C33:C37) -> 0 | E38: =SUM(E33:E37) -> 0 | G38: =SUM(G33:G37) -> 0 | I38: =SUM(I33:I37) -> 0 | K38: =SUM(K33:K37) -> 0 | M38: =SUM(M33:M37) -> 0 | O38: =SUM(O33:O37) -> 0 | Q38: =SUM(Q33:Q37) -> 0 | S38: =SUM(S33:S37) -> 0 | U38: =SUM(U33:U37) -> 0 | W38: =SUM(W33:W37) -> 0 | Y38: =SUM(Y33:Y37) -> 0 | AA38: =SUM(AA33:AA37) -> 0
B40: (-) Despesas | D40: =IFERROR((C40/C25),0) -> 0 | F40: =IFERROR((E40/E25),0) -> 0 | H40: =IFERROR((G40/G25),0) -> 0 | J40: =IFERROR((I40/I25),0) -> 0 | L40: =IFERROR((K40/K25),0) -> 0 | N40: =IFERROR((M40/M25),0) -> 0 | P40: =IFERROR((O40/O25),0) -> 0 | R40: =IFERROR((Q40/Q25),0) -> 0 | T40: =IFERROR((S40/S25),0) -> 0 | V40: =IFERROR((U40/U25),0) -> 0 | X40: =IFERROR((W40/W25),0) -> 0 | Z40: =IFERROR((Y40/Y25),0) -> 0 | AA40: =SUM(C40,E40,G40,I40,K40,M40,O40,Q40,S40,U40,W40,Y40) -> 0 | AB40: =IFERROR((AA40/AA25),0) -> 0
B41: (+/-) Outros Resultados Operacionais | D41: =IFERROR((C41/C25),0) -> 0 | F41: =IFERROR((E41/E25),0) -> 0 | H41: =IFERROR((G41/G25),0) -> 0 | J41: =IFERROR((I41/I25),0) -> 0 | L41: =IFERROR((K41/K25),0) -> 0 | N41: =IFERROR((M41/M25),0) -> 0 | P41: =IFERROR((O41/O25),0) -> 0 | R41: =IFERROR((Q41/Q25),0) -> 0 | T41: =IFERROR((S41/S25),0) -> 0 | V41: =IFERROR((U41/U25),0) -> 0 | X41: =IFERROR((W41/W25),0) -> 0 | Z41: =IFERROR((Y41/Y25),0) -> 0 | AA41: =SUM(C41,E41,G41,I41,K41,M41,O41,Q41,S41,U41,W41,Y41) -> 0 | AB41: =IFERROR((AA41/AA25),0) -> 0
B42: (+/-) Resultado Financeiro | D42: =IFERROR((C42/C25),0) -> 0 | F42: =IFERROR((E42/E25),0) -> 0 | H42: =IFERROR((G42/G25),0) -> 0 | J42: =IFERROR((I42/I25),0) -> 0 | L42: =IFERROR((K42/K25),0) -> 0 | N42: =IFERROR((M42/M25),0) -> 0 | P42: =IFERROR((O42/O25),0) -> 0 | R42: =IFERROR((Q42/Q25),0) -> 0 | T42: =IFERROR((S42/S25),0) -> 0 | V42: =IFERROR((U42/U25),0) -> 0 | X42: =IFERROR((W42/W25),0) -> 0 | Z42: =IFERROR((Y42/Y25),0) -> 0 | AA42: =SUM(C42,E42,G42,I42,K42,M42,O42,Q42,S42,U42,W42,Y42) -> 0 | AB42: =IFERROR((AA42/AA25),0) -> 0
B44: Resultado | C44: =SUM(C25+C28+C31+C38+C40+C41+C42) -> 0 | D44: =IFERROR((C44/C25),0) -> 0 | E44: =SUM(E25+E28+E31+E38+E40+E41+E42) -> 0 | F44: =IFERROR((E44/E25),0) -> 0 | G44: =SUM(G25+G28+G31+G38+G40+G41+G42) -> 0 | H44: =-IFERROR((G44/G25),0) -> 0 | I44: =SUM(I25+I28+I31+I38+I40+I41+I42) -> 0 | J44: =-IFERROR((I44/I25),0) -> 0 | K44: =SUM(K25+K28+K31+K38+K40+K41+K42) -> 0 | L44: =-IFERROR((K44/K25),0) -> 0 | M44: =SUM(M25+M28+M31+M38+M40+M41+M42) -> 0 | N44: =-IFERROR((M44/M25),0) -> 0 | O44: =SUM(O25+O28+O31+O38+O40+O41+O42) -> 0 | P44: =-IFERROR((O44/O25),0) -> 0 | Q44: =SUM(Q25+Q28+Q31+Q38+Q40+Q41+Q42) -> 0 | R44: =-IFERROR((Q44/Q25),0) -> 0 | S44: =SUM(S25+S28+S31+S38+S40+S41+S42) -> 0 | T44: =-IFERROR((S44/S25),0) -> 0 | U44: =SUM(U25+U28+U31+U38+U40+U41+U42) -> 0 | V44: =-IFERROR((U44/U25),0) -> 0 | W44: =SUM(W25+W28+W31+W38+W40+W41+W42) -> 0 | X44: =-IFERROR((W44/W25),0) -> 0 | Y44: =SUM(Y25+Y28+Y31+Y38+Y40+Y41+Y42) -> 0 | Z44: =-IFERROR((Y44/Y25),0) -> 0 | AA44: =SUM(AA25+AA28+AA31+AA38+AA40+AA41+AA42) -> 0 | AB44: =-IFERROR((AA44/AA25),0) -> 0
B47: ACOMPANHAMENTO DE ESTOQUE_2026
C49: JAN | E49: FEV | G49: MAR | I49: ABR | K49: MAI | M49: JUN | O49: JUL | Q49: AGO | S49: SET | U49: OUT | W49: NOV | Y49: DEZ | AA49: ANUAL
B50: Compras (Média)
A51: 266 | B51: Estoque Contábil | AA51: =Y51 -> 0
B52: Estoque Relatório Gerencial | AA52: =Y52 -> 0
B53: Dif. Estoque (Gerencial Vs Contábil) | C53: =C52-C51 -> 0 | E53: =E52-E51 -> 0 | G53: =G52-G51 -> 0 | I53: =I52-I51 -> 0 | K53: =K52-K51 -> 0 | M53: =M52-M51 -> 0 | O53: =O52-O51 -> 0 | Q53: =Q52-Q51 -> 0 | S53: =S52-S51 -> 0 | U53: =U52-U51 -> 0 | W53: =W52-W51 -> 0 | Y53: =Y52-Y51 -> 0 | AA53: =AA52-AA51 -> 0
B55: APURAÇÃO IRPJ E CSLL_SUSPENSÃO/REDUÇÃO_2026
C57: JAN | E57: FEV | G57: MAR | I57: ABR | K57: MAI | M57: JUN | O57: JUL | Q57: AGO | S57: SET | U57: OUT | W57: NOV | Y57: DEZ | AA57: ANUAL
...

Sheet Confrontos Federais
B3: CONFRONTOS 2023 - APURAÇÕES VS DECLARAÇÕES_IRPJ E CSLL
B4: ='Acomp. Resultados_2026'!B5:AA5 -> NOME DA EMPRESA
B5: ='Acomp. Resultados_2026'!B6:AA6 -> CNPJ DA EMPRESA:
B8: IRPJ e CSLL | C8: JAN_2026 | E8: FEV_2026 | G8: MAR_2026 | I8: ABR_2026 | K8: MAI_2026 | M8: JUN_2026 | O8: JUL_2026 | Q8: AGO_2026 | S8: SET_2026 | U8: OUT_2026 | W8: NOV_2026 | Y8: DEZ_2026 | AA8: TOTAL 2026
B10: DEMONSTRAÇÃO CONTÁBIL
B11: IRPJ | C11: ='Acomp. Resultados_2026'!C95 -> 0 | AA11: =C11+E11+G11+I11+K11+M11+O11+Q11+S11+U11+W11+Y11 -> 0
B12: CSLL | C12: ='Acomp. Resultados_2026'!C101 -> 0 | AA12: =C12+E12+G12+I12+K12+M12+O12+Q12+S12+U12+W12+Y12 -> 0
B14: MEMÓRIA DE CÁLCULO | AA14: =SUM(C14:Y14) -> 0
B15: IRPJ | C15: ='Acomp. Resultados_2026'!C95 -> 0 | AA15: =C15+E15+G15+I15+K15+M15+O15+Q15+S15+U15+W15+Y15 -> 0
B16: CSLL | C16: ='Acomp. Resultados_2026'!C101 -> 0 | AA16: =C16+E16+G16+I16+K16+M16+O16+Q16+S16+U16+W16+Y16 -> 0
B19: VALORES DECLARADOS MIT
B20: IRPJ | C20: 0 | AA20: =C20+E20+G20+I20+K20+M20+O20+Q20+S20+U20+W20+Y20 -> 0
B21: CSLL | C21: 0 | AA21: =C21+E21+G21+I21+K21+M21+O21+Q21+S21+U21+W21+Y21 -> 0
B23: VALORES RECOLHIDOS/COMPENSADO
B24: IRPJ | C24: 0 | AA24: =C24+E24+G24+I24+K24+M24+O24+Q24+S24+U24+W24+Y24 -> 0
B25: CSLL | C25: 0 | AA25: =C25+E25+G25+I25+K25+M25+O25+Q25+S25+U25+W25+Y25 -> 0
B27: CONFRONTOS | C27: JAN_2026 | E27: FEV_2026 | G27: MAR_2026 | I27: ABR_2026 | K27: MAI_2026 | M27: JUN_2026 | O27: JUL_2026 | Q27: AGO_2026 | S27: SET_2026 | U27: OUT_2026 | W27: NOV_2026 | Y27: DEZ_2026 | AA27: TOTAL 2026
B28: CONTÁBIL VS APURADO - IRPJ | C28: =C11-C15 -> 0 | E28: =E11-E15 -> 0 | G28: =G11-G15 -> 0 | I28: =I11-I15 -> 0 | K28: =K11-K15 -> 0 | M28: =M11-M15 -> 0 | O28: =O11-O15 -> 0 | Q28: =Q11-Q15 -> 0 | S28: =S11-S15 -> 0 | U28: =U11-U15 -> 0 | W28: =W11-W15 -> 0 | Y28: =Y11-Y15 -> 0 | AA28: =SUM(C28:Z28) -> 0
B29: CONTÁBIL VS APURADO - CSLL | C29: =C12-C16 -> 0 | E29: =E12-E16 -> 0 | G29: =G12-G16 -> 0 | I29: =I12-I16 -> 0 | K29: =K12-K16 -> 0 | M29: =M12-M16 -> 0 | O29: =O12-O16 -> 0 | Q29: =Q12-Q16 -> 0 | S29: =S12-S16 -> 0 | U29: =U12-U16 -> 0 | W29: =W12-W16 -> 0 | Y29: =Y12-Y16 -> 0 | AA29: =SUM(B29:Z29) -> 0
B30: APURADO VS DECLARADO - IRPJ | C30: =C15-C20 -> 0 | E30: =E15-E20 -> 0 | G30: =G15-G20 -> 0 | I30: =I15-I20 -> 0 | K30: =K15-K20 -> 0 | M30: =M15-M20 -> 0 | O30: =O15-O20 -> 0 | Q30: =Q15-Q20 -> 0 | S30: =S15-S20 -> 0 | U30: =U15-U20 -> 0 | W30: =W15-W20 -> 0 | Y30: =Y15-Y20 -> 0 | AA30: =SUM(B30:Z30) -> 0
B31: APURADO VS DECLARADO - CSLL | C31: =C16-C21 -> 0 | E31: =E16-E21 -> 0 | G31: =G16-G21 -> 0 | I31: =I16-I21 -> 0 | K31: =K16-K21 -> 0 | M31: =M16-M21 -> 0 | O31: =O16-O21 -> 0 | Q31: =Q16-Q21 -> 0 | S31: =S16-S21 -> 0 | U31: =U16-U21 -> 0 | W31: =W16-W21 -> 0 | Y31: =Y16-Y21 -> 0 | AA31: =SUM(B31:Z31) -> 0
B32: DECLARADO VS PAGO/COMPENSADO - IRPJ | C32: =C20-C24 -> 0 | E32: =E20-E24 -> 0 | G32: =G20-G24 -> 0 | I32: =I20-I24 -> 0 | K32: =K20-K24 -> 0 | M32: =M20-M24 -> 0 | O32: =O20-O24 -> 0 | Q32: =Q20-Q24 -> 0 | S32: =S20-S24 -> 0 | U32: =U20-U24 -> 0 | W32: =W20-W24 -> 0 | Y32: =Y20-Y24 -> 0 | AA32: =SUM(B32:Z32) -> 0
B33: DECLARADO VS PAGO/COMPENSADO - CSLL | C33: =C21-C25 -> 0 | E33: =E21-E25 -> 0 | G33: =G21-G25 -> 0 | I33: =I21-I25 -> 0 | K33: =K21-K25 -> 0 | M33: =M21-M25 -> 0 | O33: =O21-O25 -> 0 | Q33: =Q21-Q25 -> 0 | S33: =S21-S25 -> 0 | U33: =U21-U25 -> 0 | W33: =W21-W25 -> 0 | Y33: =Y21-Y25 -> 0 | AA33: =SUM(C33:Z33) -> 0
B35: Observações:
